Workbook

Sheet BILAN GENERAL
A1: BILAN GENERAL DE TABLEAU MARGE BENEFICIAIRE
B2: 2019 | C2: 2020 | D2: 2021 | E2: 2022 | F2: 2023 | G2: 2024 | H2: PROJECTED 2025
A3: JANV | B3: 4054748 | C3: 2708658 | D3: 2016935 | E3: 2670520 | F3: 8001529
A4: FEV | B4: 2506986 | C4: 3722151 | D4: 1172280 | E4: 2550569 | F4: 8899888
A5: MARS | B5: 3088124 | C5: 2227332 | D5: 1461243 | E5: 5112299 | F5: 7286920
A6: AVRIL | B6: 3765436 | D6: 1964055 | E6: 3749790 | F6: 6165018
A7: MAI | B7: 4087698 | D7: 1421985 | E7: 8134015 | F7: 10221695
A8: JUIN | B8: 2847899 | D8: 2235817 | E8: 6914727 | F8: 11631907
A9: JUIL | B9: 2562496 | D9: 2392760 | E9: 8444336 | F9: 10756417
A10: AOUT | B10: 3038847 | C10: 1087250 | D10: 4431247 | E10: 8414693 | F10: 10365520
A11: SEPT | B11: 3738723 | C11: 709370 | D11: 2952131 | E11: 12182359 | F11: 10640419
A12: OCT | B12: 5144842 | C12: 988155 | D12: 2545712 | E12: 10620735 | F12: 17199623
A13: NOV | B13: 2456022 | C13: 1097157 | D13: 3959852 | E13: 7686701 | F13: 13774945
A14: DEC | B14: 3078458 | C14: 1115342 | D14: 3099835 | E14: 3483357 | F14: 9705932
A15: TOTAL | B15: =SUM(B3:B14) | C15: =SUM(C3:C14) | D15: =SUM(D3:D14) | E15: =SUM(E3:E14) | F15: =SUM(F3:F14)
A17: left 13,816,262 to BEP with 2019 MARGE DE BENEFICIAIRE | C17: left 990,340 to BEP with 2020

Sheet JANVIER
A1: DATE | B1: CIES | C1: TRAVEL DATE | D1: PARCOURS | E1: N FACTURE | F1: ENTREPRISE | G1: NOMS/PRENOMS | H1: APPORTEUR | I1: TARIF HT | J1: TC | K1: TM | L1: FS | M1: LIEU ACHAT | N1: NUMERO DU BILLET | O1: NBRE SGTS | P1: AVANCE 01 | Q1: AVANCE 02 | R1: RGLT | S1: SOLDE | T1: DATE RGLT | U1: MODE RGLT | V1: OBS
A2: 45665 | B2: AF | C2: 17FEB-02MAR | D2: DLA-NTE-DLA | E2: 00008/01/2025 | F2: ADSNET | G2: KENFACK GUEFO EPSE JIOTSA EDWIGE | H2: DG | J2: 725950 | K2: 660020 | L2: =J2-K2 | M2: GOLITE | N2: ETKT 0575827796850 | O2: 4 | R2: 725950 | S2: =J2-P2-R2 | T2: 45763 | U2: BANQUE | V2: CHQ 2988599
A3: 45671 | B3: QC | C3: 16JAN. | D3: DLA-NSI-DLA | E3: 00018/01/2025 | F3: ATLANTIQUE | G3: RAOUL CHARLEMAGNE RAYMOND YAPO | H3: DG | I3: 36840 | J3: 124940 | K3: 106740 | L3: =J3-K3 | M3: KUI | N3: ETKT 0400300037012 | R3: 124940 | S3: =J3-P3-R3 | T3: 45734 | U3: BANQUE | V3: CHQ 2342450
A4: 45679 | B4: SN | C4: 03FEB-09FEB | D4: DLA-CDG-DLA | E4: 00051/01/2025 | F4: ATLANTIQUE | G4: FOTADZONG TCHIO THEOPHILE | H4: DG | J4: 2245950 | K4: 1925420 | L4: =J4-K4 | M4: NDC | N4: ETKT 0829049042116 | R4: 2245950 | S4: =J4-P4-R4 | T4: 45734 | U4: BANQUE | V4: CHQ 2342450
A5: 45681 | E5: 00057/01/2025 | F5: ATLANTIQUE | G5: FOTADZONG TCHIO THEOPHILE | H5: DG | J5: 56000 | K5: 32000 | L5: =J5-K5 | O5: VISA MAROC | R5: 56000 | S5: =J5-P5-R5 | T5: 45734 | U5: BANQUE | V5: CHQ 2342450
A6: 45687 | E6: 00080/01/2025 | F6: ATLANTIQUE | G6: FOTADZONG TCHIO THEOPHILE | J6: 946900 | O6: HERGEMENT | R6: 946900 | S6: =J6-P6-R6 | T6: 45734 | U6: BANQUE | V6: CHQ 2342450
A7: 45676 | B7: J7 | C7: 20JAN. | D7: SSG-DLA | E7: 00037/01/2025 | F7: BANGE BANK | G7: OBIANG NCHAMA JOSE MIGUEL | H7: DG | J7: 149950 | K7: 118700 | L7: =J7-K7 | M7: J7 | N7: ETKT 27722616419 | R7: 148152 | S7: =J7-P7-R7 | T7: 45695 | U7: V/R
A8: 45677 | B8: QC | C8: 21JAN-22JAN | D8: NSI-DLA-NSI | E8: 00040/01/2025 | F8: BANGE BANK | G8: MVONDO ASSAM BONAVENTURE | H8: DG | J8: 165950 | K8: 146140 | L8: =J8-K8 | M8: KIU | N8: ETKT 0400300037014 | R8: 164691 | S8: =J8-P8-R8 | T8: 45695 | U8: V/R
A9: 45680 | B9: C8 | C9: 26JAN-29JAN | D9: DLA-SSG-DLA | E9: 00053/01/2025 | F9: BANGE BANK | G9: BIYANG OBIANG ELSA ANTONIA | H9: DG | J9: 309093 | K9: 256093 | L9: =J9-K9 | M9: C8 | N9: ETKT 49850000310507 | R9: 306093 | S9: =J9-P9-R9 | T9: 45862 | U9: V/R
A10: 45680 | B10: C8 | C10: 26JAN-29JAN | D10: DLA-SSG-DLA | E10: 00053/01/2025 | F10: BANGE BANK | G10: NVE BIYANG CELEDONIO | H10: DG | J10: 26857 | K10: 16857 | L10: =J10-K10 | M10: C8 | N10: ETKT 49850 000310508 | R10: 26857 | S10: =J10-P10-R10 | T10: 45862 | U10: V/R
A11: 45686 | B11: C8 | C11: 31JAN. | D11: SSG-DLA | E11: 00081/01/2025 | F11: BANGE BANK | G11: BIYANG OBIANG ELSA ANTONIA | H11: DG | J11: 73900 | K11: 58000 | L11: =J11-K11 | M11: C8 | N11: ETKT 49850000312295 | O11: EXCHANGE | R11: 73001 | S11: =J11-P11-R11 | T11: 45695 | U11: V/R
A12: 45686 | B12: C8 | C12: 31JAN. | D12: SSG-DLA | E12: 00081/01/2025 | F12: BANGE BANK | G12: NVE BIYANG CELEDONIO | H12: DG | J12: 0 | K12: 0 | L12: =J12-K12 | M12: C8 | N12: ETKT 49850000312295 | O12: EXCHANGE | S12: =J12-P12-R12
A13: 45681 | E13: 00060/01/2025 | F13: CABINET DENTAIRE G2 | G13: GAMGNE GUIADEM CATHERINE MARCELLE | H13: DG | J13: 60000 | K13: 46000 | L13: =J13-K13 | O13: VISA | R13: 60000 | S13: =J13-P13-Q13-R13 | T13: 45676 | U13: CAISSE
A14: 45681 | B14: SN | C14: 31JAN-05FEB | D14: DLA-CDG-DLA | E14: 00065/01/2025 | F14: CABINET DENTAIRE G2 | G14: GAMGNE GUIADEM CATHERINE MARCELLE | H14: DG | J14: 2090000 | K14: 1925420 | L14: =J14-K14 | M14: NDC | N14: ETKT 0829049042122 | R14: 2090000 | S14: =J14-P14-Q14-R14 | T14: 45676 | U14: CAISSE
A15: 45684 | B15: SN | C15: 17APR. | D15: DLA-CDG | E15: 00071/01/2025 | F15: CABINET DENTAIRE G2 | G15: GAMGNE GUIADEM CATHERINE MARCELLE | H15: DG | J15: 189000 | K15: 164000 | L15: =J15-K15 | M15: SN | N15: ETKT 0823038968286 | R15: 189000 | S15: =J15-P15-Q15-R15 | T15: 45676 | U15: CAISSE
A16: 45666 | B16: KP | C16: 23JAN. | D16: NIM-DLA | E16: 00012/01/2025 | F16: CABTE | G16: ABDOULAYE ALIO MAHAMAN LAWAN | H16: DG | I16: 222000 | J16: 498600 | K16: 445280 | L16: =J16-K16 | M16: GOLITE | N16: ETKT 032587796855 | O16: 2 | R16: 498900 | S16: =J16-P16-R16 | T16: 45667 | U16: BANQUE | V16: CHQ 8484219
A17: 45673 | B17: SN | C17: 18MAR-02APR | D17: DLA-MEM-DLA | E17: 00025/01/2025 | F17: CABTE | G17: DJEUGAP EPSE NTSAGUIM FERNANDE ALIENCE | H17: DG | I17: 663800 | J17: 1168900 | K17: 1049782 | L17: =J17-K17 | M17: GOLITE | N17: ETKT 0825827796871-872 | O17: 6 | R17: 1168900 | S17: =J17-P17-R17 | T17: 45688 | U17: BANQUE | V17: CHQ 3023335
A18: 45665 | B18: QC | C18: 20JAN-23JAN | D18: DLA-NGE-DLA | E18: 00010/01/2025 | F18: CANAL+ | G18: NA IMMA AMADOU HAMIDOU | H18: DG | I18: 59340 | J18: 153640 | K18: 131640 | L18: =J18-K18 | M18: KIU | N18: ETKT 0400300037011 | R18: 153640 | S18: =J18-P18-R18 | T18: 45779 | U18: V/R
A19: 45667 | B19: ET | C19: 14JAN-04FEB | D19: DLA-BGF-DLA | E19: 00014/01/2025 | F19: CANAL+ | G19: BOUJEKE TCHEKOULONG WILLIAM | H19: DG | I19: 225100 | J19: 523900 | K19: 455947 | L19: =J19-K19 | M19: GOLITE | N19: ETKT 4595827796857 | O19: 2 | R19: 523900 | S19: =J19-P19-R19 | T19: 45779 | U19: V/R
A20: 45680 | B20: SN | C20: 09FEB-15FEB | D20: DLA-DSS-DLA | E20: 00055/01/2025 | F20: CANAL+ | G20: YOUBISSI TOWO EPSE ZEINSE F JUSTINE DIANE | H20: DG | J20: 681920 | K20: 620488 | L20: =J20-K20 | M20: GOLITE | N20: ETKT 0325827796893 | O20: 4 | R20: 681920 | S20: =J20-P20-R20 | T20: 45754 | U20: V/R
A21: 45681 | B21: QC | C21: 27JAN-27JAN | D21: DLA-NSI-DLA | E21: 00064/01/2025 | F21: CANAL+ | G21: GNABE KOUKOU MAWOUSSE | H21: DG | J21: 121740 | K21: 94340 | L21: =J21-K21 | M21: KIU | N21: ETKT 0400300037017 | S21: =J21-P21-R21
A22: 45681 | B22: QC | C22: 27JAN-27JAN | D22: DLA-NSI-DLA | E22: 00064/01/2025 | F22: CANAL+ | G22: YOUATOU PENE FABRICE | H22: DG | J22: 121740 | K22: 94340 | L22: =J22-K22 | M22: KIU | N22: ETKT 0400300037018 | S22: =J22-P22-R22
A23: 45688 | B23: WB | C23: 31JAN. | D23: BGF-DLA | E23: 00093/01/2025 | F23: CANAL+ | G23: BOUJEKE TCHEKOULONG WILLIAM | H23: DG | J23: 111950 | K23: 63000 | L23: =J23-K23 | M23: GOLITE | N23: ETKT 4595827796913 | O23: EXCHANGE | R23: 111950 | S23: =J23-P23-R23 | T23: 45754 | U23: V/R
A24: 45688 | B24: QC | C24: 02FEB-08FEB | D24: DLA-NSI-DLA | E24: 00093/01/2025 | F24: CANAL+ | G24: BOUJEKE TCHEKOULONG WILLIAM | H24: DG | I24: 33640 | J24: 119540 | K24: 86540 | L24: =J24-K24 | M24: KIU | N24: ETKT 0400300037019 | R24: 119540 | S24: =J24-P24-R24 | T24: 45754 | U24: V/R
A25: 45688 | B25: QC | C25: 02FEB. | D25: DLA-BFX | E25: 00092/01/2025 | F25: CANAL+ | G25: MAKOUGAM BRIGITTE | H25: DG | I25: 17370 | J25: 71500 | K25: 49150 | L25: =J25-K25 | M25: KIU | N25: ETKT 0400300037020 | R25: 71500 | S25: =J25-P25-R25 | T25: 45754 | U25: V/R
A26: 45688 | B26: QC | C26: 06FEB-09FEB | D26: DLA-NSI-DLA | E26: 00092/01/2025 | F26: CANAL+ | G26: MAKOUGAM BRIGITTE | H26: DG | I26: 33640 | J26: 117900 | K26: 86500 | L26: =J26-K26 | M26: KIU | N26: ETKT 0400300037021 | R26: 117900 | S26: =J26-P26-R26 | T26: 45754 | U26: V/R
A27: 45660 | B27: J7 | C27: 04JAN. | D27: BSG -DLA | E27: 00004/01/2025 | F27: DAF BANGE BANK | G27: NVE MODJO JUSTINO NGUERE | H27: DG | J27: 223900 | K27: 173900 | L27: =J27-K27 | M27: J7 | N27: ETKT 27722420665 | P27: 0 | R27: 570870 | S27: 0 | T27: 45670 | U27: CAISSE | V27: 19JAN. | W27: +237 6 98 40 54 70
A28: 45660 | B28: J7 | C28: 04JAN. | D28: BSG -DLA | E28: 00004/01/2025 | F28: DAF BANGE BANK | G28: MOHAMADOU AISSA | H28: DG | J28: 271800 | K28: 231200 | L28: =J28-K28 | M28: J7 | N28: ETKT 27722420681 | V28: 19JAN. | W28: +237 6 98 40 54 71
A29: 45660 | B29: QC | C29: 05JAN. | D29: DLA-NSI | E29: 00004/01/2025 | F29: DAF BANGE BANK | G29: NVE MODJO JUSTINO NGUERE | H29: DG | J29: 75170 | K29: 60170 | L29: =J29-K29 | M29: KIU | N29: ETKT 0400300037010 | V29: 19JAN. | W29: +237 6 98 40 54 72
A30: 45681 | B30: C8 | C30: 26JAN-29JAN | D30: DLA-SSG-DLA | E30: 00068/01/20250 | F30: DAF BANGE BANK | G30: ADIDJA TALATOU | H30: DG | J30: 256000 | K30: 256000 | L30: =J30-K30 | M30: C8 | N30: ETKT 49850000310899 | R30: 256000 | S30: =J30-P30-R30 | T30: 45726 | U30: OM
A31: 45686 | B31: C8 | C31: 31JAN. | D31: SSG-DLA | E31: 00083/01/2025 | F31: DAF BANGE BANK | G31: ADIDJA TALATOU | H31: DG | J31: 68000 | K31: 53000 | L31: =J31-K31 | M31: C8 | N31: ETKT 49850000312293 | O31: EXCHANGE | R31: 68000 | S31: =J31-P31-R31
A32: 45681 | B32: AF | C32: 13FEB-02MAR | D32: DLA-CDG-DLA | E32: 00063/01/2025 | F32: HARVEST | G32: KAMGAING MARC | H32: DG | J32: 2411900 | K32: 2266500 | L32: =J32-K32 | M32: BLUEBERRY | N32: ETKT 0572306439131 | R32: 2411900 | S32: =J32-P32-R32 | T32: 45702 | U32: V/R
A33: 45678 | F33: HORUS | G33: ONANA CYRILLE BERTRAND | H33: DG | J33: 275000 | K33: 200000 | L33: =J33-K33 | O33: VISA | R33: 275000 | S33: =J33-P33-R33 | T33: 45692 | U33: V/R
A34: 45686 | B34: EK | C34: 07FEB-10FEB | D34: CDG-DXB-CDG | E34: 00082/01/2025 | F34: HORUS | G34: ONANA CYRILLE BERTRAND | H34: DG | J34: 5897900 | K34: 5477250 | L34: =J34-K34 | M34: BLUEBERRY | N34: ETKT 1762113933918 | P34: 4441025 | R34: 1456875 | S34: =J34-P34-R34 | T34: 45715 | U34: V/R
A35: 45688 | B35: ET | C35: 07FEV-10FEB | D35: DLA-DXB-DLA | E35: 00085/01/2025 | F35: HORUS | G35: WAFO MAURICE | H35: DG | I35: 170000 | J35: 2488920 | K35: 2241020 | L35: =J35-K35 | M35: GOLLITE | N35: ETKT 0715827796914 | O35: 4 | P35: 746580 | R35: 1742340 | S35: =J35-P35-R35 | T35: 45737 | U35: V/R
A36: 45673 | B36: AT | C36: 20JAN-05MAR | D36: CMN-DLA-CMN | E36: 00023/01/2025 | F36: KALFRELEC | G36: NICORA GUY CARLO ALPHONSE | H36: DG | I36: 534500 | J36: 857950 | K36: 769675 | L36: =J36-K36 | M36: AT | N36: ETKT 0145827796875 | O36: 2 | S36: =J36-P36-R36
A37: 45682 | B37: HF | C37: 28JAN-31JAN | D37: DLA-ABJ-DLA | E37: 00070/01/2025 | F37: KETCH | G37: BETCHEM NARCISSE | H37: DG | I37: 140600 | J37: 505800 | K37: 481684 | L37: =J37-K37 | M37: GOLITE | N37: ETKT 4835827796897 | O37: 2 | P37: 300000 | R37: 831600 | S37: =J37+J38+J39+J40-P37-R37 | T37: 45692 | U37: V/R
A38: 45682 | B38: HF | C38: 28JAN-31JAN | D38: DLA-ABJ-DLA | E38: 00070/01/2025 | F38: KETCH | G38: NGOUEN, EMMANUEL | H38: DG | I38: 140600 | J38: 505800 | K38: 481684 | L38: =J38-K38 | M38: GOLITE | N38: ETKT 4835827796898 | O38: 2
A39: 45684 | B39: HF | C39: 29JAN-31JAN | D39: DLA-ABJ-DLA | E39: 00070/01/2025 | F39: KETCH | G39: BETCHEM NARCISSE | H39: DG | J39: 60000 | K39: 30000 | L39: =J39-K39 | M39: GOLITE | N39: ETKT 4835827796900 | O39: EXCHANGE
A40: 45684 | B40: HF | C40: 29JAN-31JAN | D40: DLA-ABJ-DLA | E40: 00070/01/2025 | F40: KETCH | G40: NGOUEN, EMMANUEL | H40: DG | J40: 60000 | K40: 30000 | L40: =J40-K40 | M40: GOLITE | N40: ETKT 4835827796901 | O40: EXCHANGE
...

Sheet FEVRIER
A1: DATE | B1: CIES | C1: TRAJET | D1: PARCOURS | E1: N FACTURE | F1: ENTREPRISE | G1: NOMS/PRENOMS | H1: APPORTEUR | I1: TARIF HT | J1: TC | K1: TM | L1: FS | M1: LIEU ACHAT | N1: NUMERO DU BILLET | O1: NBRE SGTS | P1: AVANCE 01 | Q1: AVANCE 02 | R1: AVANCE 03 | S1: RGLT | T1: SOLDE | U1: DATE RGLT | V1: MODE RGLT | W1: OBS
A2: 45689 | B2: J7 | C2: 04FEB-06FEB | D2: DLA-SSG-DLA | E2: 00096/02/2025 | F2: BANGE BANK | G2: OBIANG NCHAMA JOSE MIGUEL | H2: DG | I2: 217 094 | J2: 120800 | L2: 120 800 | M2: J7 | N2: ETKT 27722785148 | S2: 120800 | T2: =J2-P2-S2 | U2: 45695 | V2: V/R
A3: 45689 | B3: J7 | C3: 06FEB. | D3: SSG-DLA | E3: 00097/02/2025 | F3: BANGE BANK | G3: EKOLO TSITSI CLEMENT JANVIER | H3: DG | I3: 108 284 | J3: 75800 | L3: 75 800 | M3: J7 | N3: ETKT 27722785114 | S3: 75800 | T3: =J3-P3-S3 | U3: 45695 | V3: V/R
A4: 45689 | B4: C8 | C4: 02FEB. | D4: DLA-SSG | E4: 00102/2/2025 | F4: BANGE BANK | G4: EKOLO TSITSI CLEMENT JANVIER | H4: DG | I4: 104 970 | J4: 80000 | K4: - | L4: 80 000 | M4: C8 | N4: ETKT 49850000313098 | S4: 80000 | T4: =J4-P4-S4 | U4: 45695 | V4: V/R
A5: 45689 | B5: KP | C5: 02FEB-04FEB | D5: NSI-SSG-NSI | E5: 00095/02/2025 | F5: BANGE BANK | G5: MVONDO ASSAM BONAVENTURE | H5: DG | I5: 770900 | J5: 180000 | K5: 0 | L5: 180 000 | M5: GOLITE | N5: ETKT 0325827796917 | S5: 180000 | T5: =J5-P5-S5 | U5: 45695 | V5: V/R
A6: 45689 | B6: HF | C6: 02FEB. | D6: ABJ-DLA | E6: 00098/02/2025 | F6: RWKING | G6: KEM NOUMEDEM EPOUSE AZEMKOUO FRANCOISE | H6: DG | J6: 99900 | K6: 71 000 | L6: 28 900 | M6: GOLITE | N6: ETKT 4835827796920 | O6: EXCHANGE | S6: 100000 | T6: =J6-P6-S6 | U6: 026/02/2025 | V6: CAISSE
A7: 45689 | B7: AT | C7: 20FEB-23FEB | D7: DLA-RAK-DLA | E7: 00100/02/2025 | F7: ATLANTIQUE | G7: FOTADZONG TCHIO THEOPHILE | H7: DG | J7: 198000 | K7: -1000 | L7: 199 000 | M7: NDC | N7: ETKT 1475827796918 | O7: EXCHANGE | S7: 198000 | T7: =J7-P7-S7 | U7: 45744 | V7: BANQUE | W7: CHQ 2342450
A8: 45689 | B8: HF | C8: 02FEB. | D8: ABJ-DLA | E8: 00098/02/2025 | F8: RWKING | G8: MAGOUDJOU EPOUSE AZEMKOUO SUZANNE | H8: DG | J8: 99900 | K8: 71000 | L8: =J8-K8 | M8: GOLITE | N8: ETKT 4835827796919 | O8: EXCHANGE | S8: 100000 | T8: =J8-P8-S8 | U8: 45714 | V8: CAISSE
A9: 45690 | B9: AF | C9: 02FEB. | D9: DLA-CDG | E9: 00101/02/2025 | F9: MR ONANA | G9: TIANI VESSAH OLIVIA BIBIANA TCHANGAIN | H9: DG | J9: -293000 | L9: =J9-K9 | M9: AF | N9: ETKT 0572324013110 | O9: EXCHANGE | T9: =J9-P9-S9 | W9: -100000 | X9: PAR BLUEBERRY
A10: 45690 | B10: AF | C10: 02FEB. | D10: DLA-CDG | E10: 00099/02/2025 | F10: MR ONANA | G10: TIANI VESSAH OLIVIA BIBIANA TCHANGAIN | H10: DG | L10: - | M10: BLUEBERRY | N10: ETKT 0572306439161 | O10: EXCHANGE | T10: =J10-P10-S10
A11: 45691 | B11: AF | C11: 03FEB-13FEB | D11: DLA-CDG-DLA | E11: 000104/02/2025 | F11: HORUS | G11: ONANA CYRILLE BERTRAND | H11: DG | J11: 250000 | K11: 210 000 | L11: 40 000 | O11: CONSIEGERIE | S11: 250000 | T11: =J11-P11-S11 | U11: 45762 | V11: BANQUE | W11: CHQ 2988599
A12: 45691 | B12: QC | C12: 04FEB-11FEB | D12: DLA-BZV-DLA | E12: 00103/02/2025 | F12: MR SOLLE | G12: SOLLE GEREMIE | H12: MME HEUNA | J12: 565800 | K12: 420 314 | L12: 145 486 | M12: KIU | N12: ETKT 0400300037023 | S12: 565800 | T12: =J12-P12-S12 | U12: 030/01/2025 | V12: CAISSE
A13: 45691 | B13: J7 | C13: 04FEB-11FEB | D13: DLA-SSG-DLA | E13: 00105/02/2025 | F13: BANGE BANK | G13: ESONO OYANA ANGELICA MONAYONG | H13: DG | I13: 217 094 | J13: 429950 | K13: 386 600 | L13: 43 350 | M13: J7 | N13: ETKT 277228074439 | S13: 427252 | T13: =J13-P13-S13 | U13: 45695 | V13: V/R
A14: 45691 | B14: QC | C14: 11FEB-15FEB | D14: DLA-LBV-DLA | E14: 00111/002/2025 | F14: ISTAMA | G14: KUTCHE TAMGHE CHEVALIER DE DIEU | H14: DG | I14: 225455 | J14: 346950 | K14: 288 155 | L14: 58 795 | M14: KIU | N14: ETKT 0400300037024 | S14: 346950 | T14: =J14-P14-S14 | U14: 45660 | V14: V/R
A15: 45691 | B15: QC | C15: 11FEB-14FEB | D15: DLA-LBV-DLA | E15: 00111/02/2025 | F15: ISTAMA | G15: NJANTA EBENEZER | H15: DG | I15: 220 845 | J15: 299900 | K15: 275 955 | L15: 23 945 | M15: KIU | N15: ETKT 0400300037022 | S15: 299900 | T15: =J15-P15-S15 | U15: 45660 | V15: V/R
A16: 45692 | B16: J7 | C16: 04FEB-06FEB | D16: DLA-SSG-DLA | E16: 0108/02/2024 | F16: BANGE BANK | G16: OBIANG NCHAMA JOSE MIGUEL | H16: DG | I16: 217094 | J16: 586600 | K16: 386600 | L16: 200000 | M16: J7 | N16: ETKT 27722785148 | S16: 583002 | T16: =J16-P16-S16
A17: 45692 | C17: 08FEB-09FEB | D17: BEAUVILLE | E17: 00109/02/2025 | F17: ATLANTIQUE | G17: FOTADZONG TCHIO THEOPHILE | H17: DG | J17: 354540 | K17: 282500 | L17: 72040 | M17: FR | N17: REF 4890315659 | O17: CONSIEGERIE | S17: 354540 | T17: =J17-P17-S17 | U17: 45744 | V17: BANQUE | W17: CHQ 2342450
A18: 45692 | B18: QC | C18: 11FEB-15FEB | D18: DLA-LBV-DLA | E18: 00111/02/2025 | F18: ISTAMA | G18: YOUAGANG GOUGUEU HARRIS STEPHANE | H18: DG | I18: 225455 | J18: 346950 | K18: 306 055 | L18: 40 895 | M18: KIU | N18: ETKT 0400200515158 | S18: 346950 | T18: =J18-P18-S18 | U18: 45660 | V18: V/R
A19: 45692 | B19: J7 | C19: 04FEB-06FEB | D19: DLA-SSG-DLA | E19: 00106/20/2025 | F19: BANGE BANK | G19: OBIANG NCHAMA JOSE MIGUEL | H19: DG | I19: 217 094 | J19: 153600 | K19: - | L19: 153 600 | M19: J7 | N19: ETKT 27722785148 | S19: 153600 | T19: =J19-P19-S19 | U19: 45695 | V19: V/R
A20: 45692 | B20: KP | C20: 05FEB-08FEB | D20: NSI-SSG-NSI | E20: 0107/02/2025 | F20: BANGE BANK | G20: MVONDO ASSAM BONAVENTURE | H20: DG | I20: 957 600 | J20: 1457955 | K20: 1 299 799 | L20: 158 156 | M20: GOLITE | N20: ETKT 0325827796921 | O20: 2 | S20: 2747264 | T20: =J20+J21+J22-P20-S20
A21: 45692 | B21: KP | C21: 05FEB-08FEB | D21: NSI-SSG-NSI | E21: 00107/02/2025 | F21: BANGE BANK | G21: EKOLO TSITSI CLEMENT JANVIER | H21: DG | I21: 298 000 | J21: 650955 | K21: 552 775 | L21: 98 180 | M21: GOLITE | N21: ETKT 0325827796923 | O21: 2
A22: 45692 | B22: KP | C22: 05FEB-08FEB | D22: NSI-SSG-NSI | E22: 00107/02/2025 | F22: BANGE BANK | G22: OBIANG NCHAMA JOSE MIGUEL | H22: DG | I22: 298 000 | J22: 650955 | K22: 552 775 | L22: 98 180 | M22: GOLITE | N22: ETKT 0325827796922 | O22: 2
A23: 45693 | B23: C8 | C23: 09FEB-12FEB | D23: DLA-SSG-DA | E23: 00112/02/2025 | F23: DAF BANGE BANK | G23: NVE MODJO JUSTINO NGUERE | H23: DG | I23: 138 870 | J23: 298800 | K23: 238000 | L23: 60800 | M23: C8 | N23: ETKT 49850000314163 | S23: 298800 | T23: =J23-P23-S23 | U23: 010/03/2025 | V23: OM
A24: 45693 | B24: C8 | C24: 09FEB-12FEB | D24: DLA-SSG-DLA | E24: 00112/02/2025 | F24: DAF BANGE BANK | G24: NGUE ANNE GUILAINE | H24: DG | I24: 138 870 | J24: 298800 | K24: 238000 | L24: 60800 | M24: C8 | N24: ETKT 49850000314164 | S24: 298800 | T24: =J24-P24-S24
A25: 45693 | B25: AT | C25: 19FEB-23FEB-26FEB | D25: DLA-DXB-RAK.CMN-LFW | E25: 00113/02/2025 | F25: SAAR | G25: KAGOU GEORGES LEOPOLD | H25: DG | I25: 1 384 600 | J25: 2109000 | K25: 1783482 | L25: 325518 | M25: GOLITE | N25: ETKT 1475827796925-926 | O25: 5 | S25: 2109000 | T25: =J25-P25-S25 | U25: 45714 | V25: BANQUE | W25: CHQ 8230438
A26: 45693 | B26: AT | C26: 20FEB-27FEB | D26: DLA-RAK-DLA | E26: 00114/02/2025 | F26: ATLANTIQUE | G26: FOTADZONG TCHIO THEOPHILE | H26: DG | J26: 198000 | K26: 800 | L26: 197200 | M26: NDC | N26: ETKT 1475827796924 | O26: EXCHANGE | T26: =J26-P26-S26
A27: 45694 | B27: TK | C27: 23FEB-27FEB | D27: DLA-RAK-DLA | E27: 00110/02/2025 | F27: ASPROM | G27: AWATIO TCHINDA ALECE FRACIOLI | H27: DG | I27: 441400 | M27: GOLITE | N27: ETKT 235582779697 | T27: =J27-P27-S27 | W27: CHEQUE
A28: 45694 | B28: J7 | C28: 07FEB- | D28: SSG-DLA | E28: 00117/02/2025 | F28: BANGE BANK | G28: MVONDO ASSAM BONAVENTURE | H28: DG | I28: 108 284 | J28: 295900 | K28: 199600 | L28: 96300 | M28: J7 | N28: ETKT 27722846733 | S28: 295900 | T28: =J28-P28-S28 | U28: 45862 | V28: V/R
A29: 45694 | B29: C8 | C29: 07FEB-16FEB | D29: DLA-SSG-DLA | E29: 00115/02/2025 | F29: BANGE BANK | G29: MARAMA MANUACHE MARIO LORENZO | H29: DG | I29: 220 770 | J29: 318900 | K29: 258000 | L29: 60900 | M29: C8 | N29: ETKT 49850000314552 | S29: 316202 | T29: =J29-P29-S29 | U29: 45742 | V29: V/R
A30: 45694 | B30: SN | C30: 05MAR-11MAR | D30: DLA-CDG-DLA | E30: 00116/02/2025 | F30: MR DJOUAKA | G30: KIFACK BOUKENG EPSE DJOUAKA FLORENCE | H30: DG | I30: 782 100 | J30: 1300800 | K30: 1108020 | L30: 192780 | M30: NDC | N30: ETKT 0829049042127 | S30: 1300800 | T30: =J30-P30-S30 | U30: 45694 | V30: V/R
A31: 45694 | B31: QC | C31: 07FEB- | D31: DLA-BFX | E31: 00118/02/2025 | F31: FOKOUA ROMEO | G31: FOKOUA KUMO ROMEO ARISTIDE | H31: DG | I31: 19 370 | J31: 86950 | K31: 55670 | L31: 31280 | M31: KIU | N31: ETKT 0400300037025 | T31: =J31-P31-S31
A32: 45694 | B32: ET | C32: 15FEB- | D32: DXB-DLA | E32: 00119/02/2025 | F32: MR WAFO | G32: WAFO MAURICE | H32: DG | J32: 112000 | K32: 73500 | L32: 38500 | M32: GOLITE | N32: ETKT 0715827796928 | O32: EXCHANGE | P32: 109750 | T32: =J32-P32-S32 | U32: 006/02/2025 | V32: OM | W32: SOLDE
A33: 45694 | B33: QC | C33: 07FEB- | D33: DLA-NSI | E33: 00120/02/2025 | F33: BANGE BANK | G33: MVONDO ASSAM BONAVENTURE | H33: DG | I33: 26 370 | J33: 114950 | K33: 99770 | L33: 15180 | M33: KIU | N33: ETKT 0400300037026 | S33: 114051 | T33: =J33-P33-S33 | U33: 45742 | V33: V/R
A34: 45695 | B34: ET | C34: 24FEB-02MAR | D34: DLA-DXB-DLA | E34: 00121/002/2025 | F34: MR KENMOGNE | G34: KENMOGNE ALAIN MODESTE | H34: DG | I34: 152 000 | J34: 489820 | K34: 439820 | L34: 50000 | M34: GOLITE | N34: ETKT 0715827796929 | O34: 4 | S34: 979650 | T34: 0 | U34: 007/02/2025 | V34: CAISSE
A35: 45695 | B35: ET | C35: 24FEB-02MAR | D35: DLA-DXB-DLA | E35: 00121/02/2025 | F35: MR KENMOGNE | G35: APALA ATONGO EPSE KENMOGNE GRACE | H35: DG | I35: 152 000 | J35: 489820 | K35: 439820 | L35: 50000 | M35: GOLITE | N35: ETKT 0715827796930 | O35: 4
A36: 45695 | B36: J7 | C36: 03MAR-06MAR | D36: DLA-LBV-DLA | E36: 00122/02/2025 | F36: HARVEST | G36: KAMGAING MARC ETIENNE | H36: DG | I36: 262 673 | J36: 648700 | K36: 578700 | L36: 70000 | M36: J7 | N36: ETKT 27722860831 | S36: 648700 | T36: =J36-P36-S36 | U36: 45722 | V36: V/R
A37: 45695 | B37: J7 | C37: 26FEB-28FEB | D37: DLA-LBV-DLA | E37: 00123/02/2025 | F37: HARVEST | G37: YE SENEH POWOH INNOCENT | H37: DG | I37: 48 978 | J37: 330900 | K37: 289500 | L37: 41400 | M37: J7 | N37: ETKT 27722860417 | S37: 330900 | T37: =J37-P37-S37 | U37: 45722 | V37: V/R
A38: 45695 | B38: J7 | C38: 26FEB-28FEB | D38: DLA-LBV-DLA | E38: 00124/02/2025 | F38: HARVEST | G38: BUNANG POUEME LIONEL FRANKY | H38: DG | I38: 48 978 | J38: 330900 | K38: 289500 | L38: 41400 | M38: J7 | N38: ETKT 27722860417 | S38: 330900 | T38: =J38-P38-S38 | U38: 45722 | V38: V/R
A39: 45695 | B39: KP | C39: 09FEB-11FEB | D39: SSG-COO-NSI | E39: 00125/02/2025 | F39: BANGE BANK | G39: OBIANG NCHAMA JOSE MIGUEL | H39: DG | I39: 270 000 | J39: 760900 | K39: 711400 | L39: 49500 | M39: GOLITE | N39: ETKT 0325827796931 | O39: 4 | S39: 758202 | T39: =J39-P39-S39 | U39: 45742 | V39: V/R
A40: 45695 | B40: SN | C40: 16MAR-15APR | D40: CDG-DLA-CDG | E40: 00127/02/2025 | F40: MR POKASSA ISTAMA | G40: CHOUAIBOU POKASSA | H40: DG | J40: 139900 | K40: 107900 | L40: 32000 | M40: NDC | N40: ETKT 0829049042128 | O40: EXCHANGE | S40: 140000 | T40: =J40-P40-S40 | U40: 45695 | V40: CAISSE
...

Sheet MAR
A1: DATE | B1: CIES | C1: PARCOURS | D1: TRAVEL DATE | E1: N FACTURE | F1: ENTREPRISE | G1: NOMS/PRENOMS | H1: APPORTEUR | I1: TARIF HT | J1: TC | K1: TM | L1: FS | M1: LIEU ACHAT | N1: NUMERO DU BILLET | O1: NBRE SGTS | P1: AVANCE 1 | Q1: AVANCE 2 | R1: AVANCE 03 | S1: RGLT | T1: SOLDE | U1: DATE RGL | V1: MODE RGLT | W1: OBS | X1: VR GOLITE | Y1: GOLITE | Z1: VR CAMAIR CO | AA1: CAMAIR CO | AB1: VR B2B | AC1: B2B
A2: 45717 | B2: ET | C2: DLA-MXP.CDG-DLA | D2: 02MAR-12MAR | E2: 00198/03/2025 | F2: MRS NJOFIN | G2: NJOFIN EPSE KAMGA FLORE | H2: MME HEUNA | J2: 147400 | K2: 137500 | L2: =J2-K2 | M2: GOLITE | N2: ETKT 0719588273688 - 689 | O2: EXCHANGE | S2: 147400 | T2: =J2-P2-S2 | U2: 45719 | V2: CAISSE | W2: SOLDE | AD2: 0
A3: 45717 | B3: KP | C3: NDJ-DLA-NDJ | D3: 05MAR-08MAR | E3: 00199/03/2025 | F3: HORUS | G3: DJIKOLOUM GUESSIMBAYE AIME | H3: DG | I3: 894300 | J3: 1249950 | K3: 1141805 | L3: =J3-K3 | M3: GOLITE | N3: ETKT 0329588273690 | O3: 2 | S3: 1249950 | T3: =J3-P3-S3 | U3: 45762 | V3: BANQUE | W3: CHQ 2988599
A4: 45717 | B4: KP | C4: LFW-DLA | D4: 02MAR. | E4: 00200/03/2025 | F4: SAAR | G4: KAGOU GEORGES LEOPOLD | H4: DG | I4: 584100 | J4: 695000 | K4: 685000 | L4: =J4-K4 | M4: GOLITE | N4: ETKT 0329588273691 | O4: 1 | S4: 695000 | T4: =J4-P4-S4 | U4: 45749 | V4: BANQUE | W4: CHQ 8619291
A5: 45718 | B5: AF | C5: NSI-BLQ-NSI | D5: 02MAR-03MAY | E5: 00202/03/2025 | F5: MR KUEDA | G5: KUEDA HARMAND BERTRAND | H5: MME HEUNA | J5: 879746 | K5: 849746 | L5: =J5-K5 | M5: BLUEBERRY | N5: ETKT 0572333237561 | S5: 879800 | T5: =J5-P5-S5 | U5: 45719 | V5: CAISSE | W5: SOLDE
A6: 45719 | B6: KP | C6: NDJ-DLA-NDJ | D6: 05MAR-08MAR | E6: 00204/03/2025 | F6: HORUS | G6: ABDEL RAZIK MAHAMAT IDRISS | H6: DG | I6: 606000 | J6: 953505 | K6: 853505 | L6: =J6-K6 | M6: GOLITE | N6: ETKT 0329588273692 | O6: 2 | S6: 953505 | T6: =J6-P6-S6 | U6: 45762 | V6: BANQUE | W6: CHQ 2988599
A7: 45719 | B7: HF | C7: DLA-ABJ-DLA | D7: 05MAR-07MAR | E7: 00205/03/2025 | F7: SAAR | G7: KAGOU GEORGES LEOPOLD | H7: DG | I7: 155300 | J7: 584820 | K7: 504820 | L7: =J7-K7 | M7: GOLITE | N7: ETKT 4839588273693 | O7: 2 | S7: 584820 | T7: =J7-P7-S7 | U7: 45384 | V7: BANQUE | W7: CHQ 8619290
A8: 45719 | B8: QC | C8: DLA-NSI | D8: 03MAR. | E8: 00203/03/2025 | F8: DAF BANGE BANK | G8: JUSTINO NGUERE, NVE MODJO | H8: DG | J8: 89970 | K8: 55170 | L8: =J8-K8 | M8: KIU | N8: ETKT 0400300037046 | T8: =J8-P8-S8
A9: 45719 | B9: QC | C9: DLA-NSI | D9: 03MAR. | E9: 00203/03/2025 | F9: DAF BANGE BANK | G9: HABIB , MOHAMADOU | H9: DG | J9: 89970 | K9: 55170 | L9: =J9-K9 | M9: KIU | N9: ETKT 0400300037047 | T9: =J9-P9-S9
A10: 45720 | B10: KQ | C10: DLA-KGL | D10: 10MAR. | E10: 00207/03/2025 | F10: MRS KOUMOUSSOM | G10: KOUMOUSSOM NDJOCK MARIE ROSE | H10: MR ROMEO | I10: 93400 | J10: 250000 | K10: 234620 | L10: =J10-K10 | M10: GOLITE | N10: ETKT 7069588273694 | O10: 2 | S10: 250000 | T10: =J10-P10-S10 | U10: 45720 | V10: CAISSE
A11: 45720 | B11: QC | C11: NSI-DLA-NSI | D11: 05MAR-09MAR | E11: 00208/03/2025 | F11: BANGE BANK | G11: ESONO EDJANG JOSE MANUEL | H11: DG | J11: 35000 | K11: 24800 | L11: =J11-K11 | M11: QC | N11: ETKT 0400200522600 | O11: EXCHANGE | S11: 35000 | T11: =J11-P11-S11 | U11: 45779 | V11: V/R
A12: 45721 | B12: QC | C12: DLA-BFX-DLA | D12: 07MAR-09MAR | E12: 00209/03/2025 | F12: MR NGUIMEYA | G12: NGUIMEYA NGUEFAH PEPIN CHARLES | H12: DG | I12: 21700 | J12: 70950 | K12: 50240 | L12: =J12-K12 | M12: KIU | N12: ETKT 0400300037048 | S12: 70950 | T12: =J12-P12-S12 | U12: 45741 | V12: CAISSE | W12: SOLDE
A13: 45722 | B13: ET | C13: DLA-CAN | D13: 06MAR. | E13: 00210/03/2025 | F13: MR IGWEMEZIE | G13: IGWEZIE ELVIS IKECHUKWU | H13: MR LUCIEN | I13: 745300 | J13: 1047120 | K13: 982914 | L13: =J13-K13 | M13: GOLITE | N13: ETKT 0719588273695 | O13: 2 | P13: 800000 | S13: 247000 | T13: =J13-P13-S13 | U13: 45726 | V13: CAISSE
A14: 45722 | B14: QC | C14: DLA-NSI | D14: 06MAR. | F14: MME LEUGA | G14: EMILIENNE LEUGA EPSE KEUYAKANG | H14: MME HEUNA | J14: 69950 | K14: 41870 | L14: =J14-K14 | M14: KIU | N14: ETKT 0400300037049 | S14: 65950 | T14: =J14-P14-S14 | U14: 45748 | V14: CAISSE | W14: SOLDE
A15: 45723 | B15: C8 | C15: DLA-SSG-DLA | D15: 12MAR-19MAR | E15: 00211/03/2025 | F15: BANGE BANK | G15: NGALLE MIANO MAY DAPHNE | H15: DG | J15: 352950 | K15: 288000 | L15: =J15-K15 | M15: C8 | N15: ETKT 49850000322941 | S15: 348822 | T15: =J15-P15-S15 | U15: 45779 | V15: V/R
A16: 45724 | B16: ET | C16: DLA-BGF-DLA | D16: 16MAR-20MAR | F16: AFG- ASSURANCE | G16: FOTADZONG TCHIO THEOPHILE | H16: DG | I16: 342800 | J16: 0 | K16: 0 | L16: =J16-K16 | M16: GOLITE | N16: ETKT 0719588273696 | O16: REFUND | T16: =J16-P16-S16
A17: 45725 | B17: KP | C17: DLA-BGF-DLA | D17: 16MAR-20MAR | E17: 00212/03/2025 | F17: AFG- ASSURANCE | G17: FOTADZONG TCHIO THEOPHILE | H17: DG | I17: 342800 | J17: 1075900 | K17: 721555 | L17: =J17-K17 | M17: GOLITE | N17: ETKT 0329588273697 | O17: 2 | S17: 1075900 | T17: =J17-P17-S17 | U17: 45789 | V17: BANQUE | W17: CHQ2342423
A18: 45726 | B18: QC | C18: DLA-NSI | D18: 11MAR. | E18: 00237/03/2025 | F18: MR TOGNIA | G18: TOGNIA BERTRAND | H18: DG | J18: 71870 | K18: 66870 | L18: =J18-K18 | M18: QC | N18: ETKT 0400300037051 | T18: =J18-P18-S18 | W18: 10MARS.
A19: 45727 | B19: AF | C19: ABJ-CDG-ABJ | D19: 14MAR-25MAR | E19: 00214/03/2025 | F19: MR ONANA | G19: LOHOUES YEMELY EMMANUELLA JESUS | H19: DG | J19: 7981800 | K19: 6861700 | L19: =J19-K19 | M19: AMADEUS | N19: ETKT 0713578260355 | P19: 3561945 | S19: 4419855 | T19: =J19-P19-S19 | U19: 14/03/2025 22/04/205 | V19: CAISSE
A20: 45727 | B20: AF | C20: CDG-IAH-CDG | D20: 15MAR-24MAR | E20: 00215/03/2025 | F20: MR ONANA | G20: LOHOUES YEMELY EMMANUELLA JESUS | H20: DG | J20: 5955900 | K20: 5655300 | L20: =J20-K20 | M20: AMADEUS | N20: ETKT 0713578260356 | P20: 580145 | S20: 5375755 | T20: =J20-P20-S20 | U20: 22/04/2025 25/04/2025 | V20: CAISSE
A21: 45727 | B21: C8 | C21: DLA-SSG. | D21: 12MAR. | E21: 00216/03/2025 | F21: BANGE BANK | G21: OBIANG NCHAMA JOSE MICHEL | H21: DG | J21: 252950 | K21: 196000 | L21: =J21-K21 | M21: C8 | N21: ETKT 49850000323756 | S21: 250253 | T21: =J21-P21-S21 | U21: 45779 | V21: V/R
A22: 45727 | B22: C8 | C22: DLA-SSG-DLA | D22: 12MAR-16MAR | E22: 00217/03/2025 | F22: BANGE BANK | G22: NGALLE MIANO MAY DAPHNE | H22: DG | J22: 60000 | K22: 35000 | L22: =J22-K22 | M22: C8 | N22: ETKT 49850000322941.324029 | O22: EXCHANGE | S22: 60000 | T22: =J22-P22-S22 | U22: 45779 | V22: V/R
A23: 45727 | B23: KP | C23: DLA-COO-DLA | D23: 17MAR-19MAR | E23: 00218/03/2025 | F23: BANGE BANK | G23: ESONO OYANA ANGELICA MONAYONG | H23: DG | I23: 208100 | J23: 720950 | K23: 645230 | L23: =J23-K23 | M23: GOLITE | N23: ETKT 0329588273698 | O23: 4 | S23: 715553 | T23: =J23-P23-S23 | U23: 45779 | V23: V/R
A24: 45727 | B24: HF | C24: DLA-ABJ. | D24: 13APR. | E24: 00219/03/2025 | F24: SMC | G24: HOT JUNIOR THIERRY | H24: DG | I24: 592200 | J24: 949900 | K24: 869120 | L24: =J24-K24 | M24: GOLITE | N24: ETKT 4839588273699 | O24: 1 | S24: 949900 | T24: =J24-P24-S24 | U24: 45728 | V24: CAISSE
A25: 45727 | B25: SN | C25: DLA-BCN.MAD-DLA | D25: 03APR-11APR | E25: 00213/03/2025 | F25: MR DJOUAKA | G25: DOUAKA ROGER ALAIN | H25: DG | I25: 992600 | J25: 1385920 | K25: 1302920 | L25: =J25-K25 | M25: NDC | N25: ETKT 0829049042136-137 | S25: 1385920 | T25: =J25-P25-S25 | U25: 45727 | V25: V/R | W25: CHQ 8815107
A26: 45727 | B26: SN | C26: DLA-BCN.MAD-DLA | D26: 03APR-11APR | E26: 00213/03/2025 | F26: MR DJOUAKA | G26: KIFACK BOUKENG EPSE DJOUAKA FLORENCE | H26: DG | I26: 992600 | J26: 1385920 | K26: 1302920 | L26: =J26-K26 | M26: NDC | N26: ETKT 0829049042138-139 | S26: 1385920 | T26: =J26-P26-S26 | U26: 45727 | V26: V/R | W26: CHQ 8815107
A27: 45728 | B27: C8 | C27: DLA-SSG | D27: 12MAR. | F27: BANGE BANK | G27: OBIANG NCHAMA JOSE MICHEL | H27: DG | J27: 252950 | K27: 196000 | L27: =J27-K27 | M27: C8 | N27: ETKT 49850000323756 | T27: =J27-P27-S27
A28: 45728 | B28: KP | C28: DLA-DSS-DLA | D28: 11MAY-17MAY | E28: 00220/03/2025 | F28: CANAL+ | G28: ZIIDANG HABIBA DANIELLE | H28: DG | I28: 167200 | J28: 678950 | K28: 618520 | L28: =J28-K28 | M28: GOLITE | N28: ETKT 0329588273700 | O28: 4 | S28: 678950 | T28: =J28-P28-S28 | U28: 45768 | V28: V/R
A29: 45728 | B29: KP | C29: DLA-DSS-DLA | D29: 11MAY-21MAY | E29: 00221/03/2025 | F29: CANAL+ | G29: NA IMMA AMMADOU HAMIDOU | H29: DG | I29: 147900 | J29: 670950 | K29: 599220 | L29: =J29-K29 | M29: GOLITE | N29: ETKT 0329588273701 | O29: 4 | S29: 670950 | T29: =J29-P29-S29 | U29: 45768 | V29: V/R
A30: 45728 | B30: SN | C30: DLA-BCN.MAD-DLA | D30: 03APR-10APR | E30: 00213/03/2025 | F30: MR DJOUAKA | G30: DOUAKA ROGER ALAIN | H30: DG | I30: 0 | J30: 146200 | K30: 131200 | L30: =J30-K30 | M30: NDC | N30: ETKT 0829049042140-141 | O30: EXCHANGE | S30: 146200 | T30: =J30-P30-S30 | U30: 45803 | V30: V/R
A31: 45728 | B31: SN | C31: DLA-BCN.MAD-DLA | D31: 03APR-10APR | E31: 00213/03/2025 | F31: MR DJOUAKA | G31: KIFACK BOUKENG EPSE DJOUAKA FLORENCE | H31: DG | I31: 0 | J31: 146200 | K31: 131200 | L31: =J31-K31 | M31: NDC | N31: ETKT 0829049042142-143 | O31: EXCHANGE | S31: 146200 | T31: =J31-P31-S31 | U31: 45803 | V31: V/R
A32: 45728 | B32: SN | C32: DLA-BRU-DLA | D32: 13APR-08MAY | E32: 00223/03/2025 | F32: SMC | G32: DIBOUSSI MARIE ANGELE | H32: DG | I32: 455000 | J32: 725500 | K32: 675320 | L32: =J32-K32 | M32: NDC | N32: ETKT 0829049042144 | S32: 725500 | T32: =J32-P32-S32 | U32: 45728 | V32: CAISSE
A33: 45729 | B33: AT | C33: CDG-DLA. | D33: 14MAR. | E33: 00224/03/2025 | F33: MR DJAPOM | G33: DJAPOM NANA JOB STEPHANE | H33: MR STEPHANE | I33: 152200 | J33: 309500 | K33: 309500 | L33: =J33-K33 | M33: GOLITE | N33: ETKT 1479588273702 | O33: 2 | T33: =J33-P33-S33 | W33: 21MARS
A34: 45730 | B34: ET | C34: DLA-CAN-DLA | D34: 24MAR-05APR | E34: 00225/03/2025 | F34: MRS BIKONG | G34: SIMEU BEATRICE | H34: DG | J34: 905000 | K34: 832520 | L34: =J34-K34 | M34: B2B | N34: ETKT 0712151317279 | P34: 765000 | T34: =J34-P34-S34 | U34: 45730 | V34: CAISSE
A35: 45730 | B35: ET | C35: DLA-CAN-DLA | D35: 24MAR-05APR | E35: 00227/03/2025 | F35: SAFARI LOGISTIQUE | G35: TCHATCHOUA SUZANNE LINDA | H35: DG | J35: 2098800 | K35: 1383300 | L35: =J35-K35 | M35: AMADEUS | N35: ETKT 0713578262958 | P35: 2000000 | S35: 98800 | T35: =J35-P35-S35 | U35: 45737 | V35: BANQUE | W35: CHQ0000116
A36: 45730 | B36: ET | C36: DLA-CAN-DLA | D36: 24MAR-05APR | E36: 00227/03/2025 | F36: SAFARI LOGISTIQUE | G36: TINA ONGOLO CLAIRE FLORA | H36: DG | J36: 905000 | K36: 832520 | L36: =J36-K36 | M36: B2B | N36: ETKT 0712151317280 | S36: 905000 | T36: =J36-P36-S36 | U36: 45790 | V36: BANQUE | W36: CHQ0000127
A37: 45730 | B37: ET | C37: DLA-CAN-DLA | D37: 24MAR-05APR | E37: 00227/03/2025 | F37: SAFARI LOGISTIQUE | G37: YAMGOUE DEBANA CHRISTELLE YOLANDE | H37: DG | J37: 905000 | K37: 832520 | L37: =J37-K37 | M37: B2B | N37: ETKT 0712151317281 | S37: 905000 | T37: =J37-P37-S37 | U37: 45790 | V37: BANQUE | W37: CHQ0000127
A38: 45730 | B38: SA | C38: JNB-CPT | D38: 24MAR. | E38: 00228/03/2025 | F38: HORUS | G38: ONANA CYRILLE BERTRAND | H38: DG | J38: 464900 | K38: 330800 | L38: =J38-K38 | M38: SATGURU | N38: ETKT 0833576107301 | S38: 464900 | T38: =J38-P38-S38 | U38: 45762 | V38: V/R
A39: 45730 | B39: SA | C39: JNB-CPT | D39: 24MAR. | E39: 00228/03/2025 | F39: HORUS | G39: NGANI MEIGNIDON DIFFO MIRELLE NICAISE | H39: DG | J39: 282600 | K39: 152700 | L39: =J39-K39 | M39: SATGURU | N39: ETKT 0833576107302 | S39: 282600 | T39: =J39-P39-S39 | U39: 45762 | V39: V/R
A40: 45731 | B40: C8 | C40: SSG-DLA | D40: 16MAR. | E40: 00229/03/2025 | F40: BANGE BANK | G40: OBIANG NCHAMA JOSE MICHEL | H40: DG | J40: 247000 | K40: 167000 | L40: =J40-K40 | M40: C8 | N40: ETKT 49850000325117 | S40: 243402 | T40: =J40-P40-S40 | U40: 45779 | V40: V/R
...

Sheet APRIL
A1: DATE | B1: CIES | C1: PARCOURS | D1: TRAVEL DATE | E1: N FACTURE | F1: ENTREPRISE | G1: NOMS/PRENOMS | H1: APPORTEUR | I1: TARIF HT | J1: TC | K1: TM | L1: FS | M1: LIEU ACHAT | N1: NUMERO DU BILLET | O1: NBRE SGTS | P1: AVANCE 01 | Q1: AVANCE 02 | R1: AVANCE 03 | S1: RGLT | T1: SOLDE | U1: DATE REGLT | V1: MODE RGLT | W1: DELAIS | X1: TMG | Y1: OV GOLITE | Z1: GOLITE | AA1: ECART | AB1: VU | AC1: DATE/HEUR
A2: 45748 | B2: QC | C2: DLA-NSI | D2: 01APR. | E2: 00287/04/2025 | F2: CANAL+ | G2: HUGUES YANNICK, TA BI TAH | H2: DG | I2: 21070 | J2: 76980 | K2: 66870 | L2: =J2-K2 | M2: KIU | N2: ETKT 0400300037068 | S2: 76980 | T2: =J2-P2-S2 | U2: 45779 | V2: V/R | X2: 0 | AC2: 228803
A3: 45748 | B3: QC | C3: DLA-NSI-DLA | D3: 03APR-04APR | E3: 00285/04/2025 | F3: CANAL+ | G3: DEBOMBO MARTIAL JUNIOR | H3: DG | J3: 138970 | K3: 83670 | L3: =J3-K3 | M3: QC | N3: ETKT 0400200535091 | O3: EXCHANGE | S3: 138970 | T3: =J3-P3-S3 | U3: 45768 | V3: V/R | X3: 0 | Z3: 1771550
A4: 45748 | B4: WB | C4: DLA-BGF | D4: 04APR. | E4: 00286/04/2025 | F4: CANAL+ | G4: DEBOMBO MARTIAL JUNIOR | H4: DG | I4: 120300 | J4: 320980 | K4: 254955 | L4: =J4-K4 | M4: GOLITE | N4: ETKT 4599588273727 | O4: 1 | S4: 320980 | T4: =J4-P4-S4 | U4: 45768 | V4: V/R | X4: =K4 | Y4: 6000000 | Z4: =Z3+Y4-X4 | AB4: 7771550 | AC4: 0
A5: 45749 | B5: AF | C5: DLA-CDG-DLA | D5: 05APR-12APR | E5: 00290/04/2025 | F5: CANAL+ | G5: KAMDEM KONMOGNE NASSER | H5: DG | I5: 2302100 | J5: 2698980 | K5: 2647920 | L5: =J5-K5 | M5: GOLITE | N5: ETKT 0579588273728 | O5: 2 | S5: 2698900 | T5: =J5-P5-S5 | U5: 45779 | V5: V/R | X5: =K5 | Z5: =Z4-X5 | AB5: 4607930
A6: 45749 | B6: SN | C6: BRU-OUA-BRU | D6: 17DEC-30DEC | E6: 00289/04/2025 | F6: SMC | G6: BARRY YACINE RAISSA | H6: DG | I6: 347700 | J6: 575700 | K6: 515700 | L6: =J6-K6 | M6: NDC | N6: ETKT 0829049042850 | P6: 575700 | T6: =J6-P6-S6 | X6: =K6 | Z6: =Z5-X6 | AB6: 4607930
A7: 45749 | B7: SN | C7: BRU-ABJ-BRU | D7: 23MAY-31MAY | E7: EN ATTENTE DE SURCLASSEMENT PAR SN BRUSSEL | F7: SMC | G7: HOT TIERRRY JUNIOR | H7: DG | J7: 179100 | K7: 129100 | L7: =J7-K7 | M7: SN | N7: ETKT 0822301014206 | O7: EXCHANGE | T7: =J7-P7-S7 | X7: 0 | Z7: =Z6-X7
A8: 45750 | B8: AF | C8: DLA-BQC-DLA | D8: 07APR-21APR | E8: 00277/04/2025 | F8: HOD INVESTMENT | G8: NGANI MEIGNIDON DIFFO, MIRELLE NICAISE ELIS | H8: DG | J8: 1798800 | K8: 1741120 | L8: =J8-K8 | M8: GOLITE | N8: ETKT 0579588273729-730 | O8: 6 | S8: 1798800 | T8: =J8-P8-S8 | U8: 45756 | V8: V/R | X8: =K8 | Z8: =Z7-X8
A9: 45750 | B9: KQ | C9: DLA-DBX | D9: 22APR. | E9: 00291/04/2025 | F9: MRS MAFFO | G9: MAFFO NDE TATSING, GERMAINE | H9: MR LUCIEN | J9: 282000 | K9: 262920 | L9: =J9-K9 | M9: GOLITE | N9: ETKT 7069588273731 | O9: 2 | S9: 282000 | T9: =J9-P9-S9 | U9: 45750 | V9: CAISSE | X9: =K9 | Z9: =Z8-X9 | AB9: 570050
A10: 45750 | B10: QC | C10: NSI-DLA | D10: 03APR. | E10: 00292/04/2025 | F10: BANGE BANK | G10: EKIRI MBANG MIGUEL JESUS | H10: DG | J10: 116700 | K10: 86670 | L10: =J10-K10 | M10: QC | N10: ETKT 0400200533681 | S10: 347402 | T10: =J10+J11+J12-P10-S10 | U10: 45779 | V10: V/R | X10: 0 | Z10: =Z9-X10
A11: 45750 | B11: QC | C11: NSI-DLA | D11: 03APR. | E11: 00292/04/2025 | F11: BANGE BANK | G11: GARRIGA OBIANG TEODORO ALBERTO | H11: DG | J11: 116700 | K11: 86670 | L11: =J11-K11 | M11: QC | N11: ETKT 0400200533682 | X11: 0 | Z11: =Z10-X11
A12: 45750 | B12: QC | C12: NSI-DLA | D12: 03APR. | E12: 00292/04/2025 | F12: BANGE BANK | G12: TNUG OBONO JACINTO NGUEMA | H12: DG | J12: 116700 | K12: 91670 | L12: =J12-K12 | M12: QC | N12: ETKT 0400200533683 | X12: 0 | Z12: =Z11-X12
A13: 45751 | B13: KP | C13: DLA-LFW-DLA | D13: 06JUL-11JUL | E13: 00294/04/2025 | F13: MRS GUIFO | G13: GUIFO AURELIE NICOLE | H13: DG | I13: 153900 | J13: 458920 | K13: 406120 | L13: =J13-K13 | M13: GOLITE | N13: ETKT 0329588273732 | O13: 2 | S13: 458920 | T13: =J13-P13-S13 | U13: 45777 | V13: CAISSE | W13: 45797 | X13: =K13 | Z13: =Z12-X13
A14: 45751 | B14: KQ | C14: DLA-CPT-DLA | D14: 06APR-10APR | E14: 00293/04/2025 | F14: MR DONGHO | G14: DONGHO DONGMO, THIERRY | H14: MR STEPHANE | J14: 1762720 | K14: 1627720 | L14: =J14-K14 | M14: AMADEUS | N14: ETKT 706 6376915934 | S14: 2075000 | T14: =J14+J15-S14 | U14: 45751 | V14: CAISSE | X14: =K14 | Z14: =Z13-X14
A15: 45751 | B15: SA | C15: JNB-CPT-JNB | D15: 07APR-10APR | E15: 00293/04/2025 | F15: MR DONGHO | G15: DONGHO DONGMO, THIERRY | H15: MR STEPHANE | J15: 312180 | K15: 296700 | L15: =J15-K15 | M15: SATGURU | N15: ETKT 0836376915807 | X15: 0 | Z15: =Z14-X15 | AA15: 254995 | AB15: 570050
A16: 45751 | B16: KP | C16: DLA-ABJ-NSI | D16: 10MAY-13MAY | E16: 00295/04/2025 | F16: HARVEST | G16: KAMGAING TAASSI MARC ETIENNE | H16: DG | J16: 213000 | K16: 204000 | L16: =J16-K16 | M16: GOLITE | N16: ETKT 0329588273733 | O16: EXCHANGE | S16: 213000 | T16: =J16-P16-S16 | U16: 45779 | V16: V/R | X16: 204000 | Z16: =Z15-X16 | AA16: =AB16-Z16 | AB16: 366050
A17: 45755 | B17: JL | C17: LHR-HND | D17: 16APR. | E17: 00279/04/2025 | F17: PIVOTAL AFRICA NETWORK | G17: HOT THIERRY JUNIOR | H17: DG | J17: 5785800 | K17: 5492800 | L17: =J17-K17 | M17: BLUEBERRY | N17: ETKT 1692820683897 | T17: =J17-P17-S17
A18: 45755 | B18: AF | C18: DEL-IAD-ABJ | D18: 23APR-27APR | E18: 00283/04/2025 | F18: PIVOTAL AFRICA NETWORK | G18: ACOUETEY KANGNI DIDIER | H18: DG | J18: 11040800 | K18: 10939200 | L18: =J18-K18 | M18: BLUEBERRY | N18: ETKT 0576376915564 | T18: =J18-P18-S18
A19: 45755 | B19: ET | C19: DLA-COO | D19: 08MAY. | E19: 00284/04/2025 | F19: PIVOTAL AFRICA NETWORK | G19: HOT THIERRY JUNIOR | H19: DG | I19: 690900-620920=69980 | J19: 159473 | K19: 49473 | L19: =J19-K19 | M19: BLUEBERRY | N19: ETKT 0716376915537 | O19: REFUND | T19: =J19-P19-S19
A20: 45755 | B20: HF | C20: COO-ABJ | D20: 10MAY. | E20: 00284/04/2025 | F20: PIVOTAL AFRICA NETWORK | G20: HOT THIERRY JUNIOR | H20: DG | I20: 938700-843700=95000 | J20: 169472 | K20: 50000 | L20: =J20-K20 | M20: BLUEBERRY | N20: ETKT 4836376915538 | O20: REFUND | T20: =J20-P20-S20
A21: 45755 | B21: AF | C21: ABJ-CDG | D21: 14APR. | E21: 00278/04/2025 | F21: PIVOTAL AFRICA NETWORK | G21: HOT THIERRY JUNIOR | H21: DG | J21: 2857500 | K21: 2734100 | L21: =J21-K21 | M21: BLUEBERRY | N21: ETKT 0576376915531 | T21: =J21-P21-S21
A22: 45755 | B22: AF | C22: HND-CDG-NKC | D22: 20APR. | E22: 00282/04/2025 | F22: PIVOTAL AFRICA NETWORK | G22: TAH SIDI | H22: DG | I22: 3551900-3461900=90000 | J22: 335800 | K22: 0 | L22: =J22-K22 | M22: BLUEBERRY | N22: ETKT 0576776915528 | O22: REFUND | T22: =J22-P22-S22
A23: 45755 | B23: JL | C23: LHR-HND | D23: 16APR. | E23: 00281/04/2025 | F23: PIVOTAL AFRICA NETWORK | G23: TAH SIDI | H23: DG | J23: 5785800 | K23: 5492800 | L23: =J23-K23 | M23: BLUEBERRY | N23: ETKT 1692820683885 | T23: =J23-P23-S23
A24: 45755 | B24: AF | C24: HND-CDG-ZYR | D24: 20APR. | E24: 00280/04/2025 | F24: PIVOTAL AFRICA NETWORK | G24: HOT THIERRY JUNIOR | H24: DG | J24: 3277500 | K24: 3187500 | L24: =J24-K24 | M24: BLUEBERRY | N24: ETKT 0576376915529 | T24: =J24-P24-S24 | Y24: 10000000 | Z24: 10366050 | AB24: 10366050
A25: 45755 | B25: ET | C25: DLA-CAN-DLA | D25: 10APR-01MAY | E25: 00299/04/2025 | F25: NGC | G25: ANTHONIA MESEH EPSE MBAKOP/XXX MRS | H25: MR LUCIEN | I25: 457600 | J25: 894900 | K25: 839420 | L25: =J25-K25 | M25: ET | N25: ETKT 0712151802925 | P25: 200000 | S25: 694900 | T25: =J25-P25-S25 | U25: 21/04/2025 23/04/2025 | V25: CAISSE | X25: 0 | AB25: 10366050
A26: 45755 | B26: AT | C26: NSI-YUL-NSI | D26: 08JUL-22AUG | E26: 00298/04/2025 | F26: MR HILAIRE | G26: VOUFFO TOUTSOP EP TAKOUEZIM, JOSEPHINE | H26: DG | I26: 351000 | J26: 823980 | K26: 786020 | L26: =J26-K26 | M26: GOLITE | N26: ETKT 1479588273736 | O26: 4 | S26: 823920 | T26: =J26-P26-S26 | U26: 45754 | V26: V/R | X26: =K26 | AB26: =AB25-X26
A27: 45755 | B27: TK | C27: DLA-HAJ | D27: 10APR. | E27: 00296/04/2025 | F27: MR LOUIS | G27: DJOMY TCHOUABIA/FLORIS JOSY MRS | H27: DG | I27: 277400 | J27: 555920 | K27: 494120 | L27: =J27-K27 | M27: GOLITE | N27: ETKT 2359588273735 | O27: 2 | P27: 551000 | T27: =J27-P27-S27 | U27: 45755 | V27: CAISSE | X27: =K27 | AB27: =#REF!-X27
A28: 45755 | B28: AF | C28: DLA-CDG-DLA | D28: 10APR-09MAY | E28: 00297/04/2025 | F28: MR TCHATUE | G28: SONE EKOLO, XAVIER YANNICK BENJAMIN | H28: DG | I28: 353200 | J28: 709800 | K28: 668420 | L28: =J28-K28 | M28: GOLITE | N28: ETKT 0579588273734 | O28: 2 | P28: 755000 | S28: 200000 | T28: =J28+J29-P28-S28 | U28: 45757 | V28: OM CAISSE | X28: =K28 | AB28: =AB27-X28
A29: 45756 | B29: AF | C29: DLA-CDG-DLA | D29: 16APR-09MAY | E29: 00303/04/2025 | F29: MR TCHATUE | G29: SONE EKOLO, XAVIER YANNICK BENJAMIN | H29: DG | I29: 0 | J29: 249800 | K29: 199100 | L29: =J29-K29 | M29: GOLITE | N29: ETKT 0579588273739 | O29: EXCHANGE | U29: 45758 | X29: =K29 | Z29: 5191540 | AB29: =AB27-X29 | AC29: 10042025T0840
A30: 45756 | B30: AF | C30: DLA-CDG-DLA | D30: 20APR-05JUL | E30: 00300/04/2025 | F30: MRS MOKAM | G30: MOKAM EPSE KAMGA, MARIE GISELE MRS | H30: MME HEUNA | I30: 519600 | J30: 862800 | K30: 827820 | L30: =J30-K30 | M30: GOLITE | N30: ETKT 0579588273737 | O30: 2 | S30: 862800 | T30: =J30-P30-S30 | U30: 45756 | V30: CAISSE | X30: =K30 | AB30: =AB27-X30
A31: 45756 | B31: AF | C31: NSI-CDG-NSI | D31: 13APR-18APR | E31: 00301/04/2025 | F31: SMC | G31: ETOUNDI BIYIDI, SIMON PIERRE | H31: DG | I31: 353200 | J31: 725820 | K31: 661420 | L31: =J31-K31 | M31: GOLITE | N31: ETKT 0579588273738 | O31: 2 | T31: =J31-P31-Q31-R31-S31 | X31: =K31 | AB31: =AB30-X31
A32: 45756 | B32: ET | C32: DLA-CAN-DLA | D32: 15APR-21APR | E32: 00302/04/2025 | F32: NGC | G32: OZIOKO/PASCHAL EMEKA | H32: MR LUCIEN | I32: 457600 | J32: 907900 | K32: 852620 | L32: =J32-K32 | M32: ET | N32: ETKT 0712151831577 | S32: 907900 | T32: =J32-P32-S32 | U32: 45770 | V32: CAISSE | X32: 0 | AB32: =AB31-X32
A33: 45756 | B33: ET | C33: DLA-NDJ-DLA | D33: 10APR-13APR | E33: 00304/04/2025 | F33: KAGOU | G33: KAGOU GEORGES LEOPOLD | H33: DG | J33: 809805 | K33: 768805 | L33: =J33-K33 | M33: AMADEUS | N33: ETKT 0716376917938 | S33: 809805 | T33: =J33-P33-Q33-R33-S33 | U33: 45763 | V33: CAISSE | X33: =K33 | AB33: =AB32-X33
A34: 45756 | B34: ET | C34: DLA-NDJ-DLA | D34: 10APR-13APR | E34: 00305/04/2025 | F34: KAGOU | G34: DJUIKOUO JOSEPHINE | H34: DG | J34: 809805 | K34: 768805 | L34: =J34-K34 | M34: AMADEUS | N34: ETKT 0716376917936 | S34: 809805 | T34: =J34-P34-Q34-R34-S34 | U34: 45763 | V34: CAISSE | X34: =K34 | AB34: =AB33-X34
A35: 45756 | B35: ET | C35: DLA-CAN-DLA | D35: 14APR-03MAY | E35: 00308/04/2025 | F35: MME CHIMENE | G35: MARTIAL TCHOUALA NDZE | H35: DG | J35: 885900 | K35: 857420 | L35: =J35-K35 | M35: B2B | N35: ETKT 0712151861118 | S35: 885900 | T35: =J35-P35-Q35-R35-S35 | U35: 45756 | V35: CAISSE | X35: 0 | AB35: =AB34-X35
A36: 45756 | B36: ET | C36: DLA-CAN-DLA | D36: 14APR-03MAY | E36: 00308/04/2025 | F36: MME CHIMENE | G36: CHIMENE NZAMESSHA NDZE EPSE YOMI | H36: DG | J36: 885900 | K36: 857420 | L36: =J36-K36 | M36: B2B | N36: ETKT 0712151861120 | S36: 885900 | T36: =J36-P36-Q36-R36-S36 | U36: 45756 | V36: CAISSE | X36: 0 | AB36: =AB35-X36
A37: 45756 | B37: ET | C37: DLA-CAN-DLA | D37: 14APR-03MAY | E37: 00308/2025 | F37: MME CHIMENE | G37: JEAN JACQUES TALONPA NZOULEWA | H37: DG | J37: 885900 | K37: 857420 | L37: =J37-K37 | M37: B2B | N37: ETKT 0712151861121 | S37: 885900 | T37: =J37-P37-Q37-R37-S37 | U37: 45792 | V37: CAISSE | X37: 0 | AB37: =AB36-X37
A38: 45757 | B38: AF | C38: CDG-JFK-CDG | D38: 21APR-26APR | E38: 00307/04/2025 | F38: HARVEST | G38: MARC KAMGAING | H38: DG | J38: 4556900 | K38: 4369100 | L38: =J38-K38 | M38: AF | N38: ETKT 0572334342393 | S38: 4556900 | T38: =J38-P38-S38 | U38: 45779 | V38: V/R | X38: 0 | AB38: =#REF!-X38
A39: 45757 | B39: AF | C39: CDG-JFK-CDG | D39: 21APR-26APR | E39: 00307/04/2025 | F39: HARVEST | G39: MAYLEE KAMGAING | H39: DG | J39: 1140600 | K39: 1086600 | L39: =J39-K39 | M39: AF | N39: ETKT 0572334342392 | S39: 1140600 | T39: =J39-P39-S39 | U39: 45779 | V39: V/R | X39: 0 | AB39: =AB38-X39
A40: 45757 | B40: AF | C40: CDG-JFK-CDG | D40: 21APR-26APR | E40: 00307/04/2025 | F40: HARVEST | G40: MAYANE KAMGAING | H40: DG | J40: 1140600 | K40: 1086600 | L40: =J40-K40 | M40: AF | N40: ETKT 0572334342391 | S40: 1140600 | T40: =J40-P40-S40 | U40: 45779 | V40: V/R | X40: 0 | AB40: =AB39-X40
...

Sheet MAY
A1: DATE | B1: CIES | C1: TRAVEL DATE | D1: PARCOURS | E1: N FACTURE | F1: ENTREPRISE | G1: NOMS/PRENOMS | H1: APPORTEUR | I1: TARIF HT | J1: COM, HF (6% ) | K1: COM, MS (7% ) | L1: COM, KP (6% ) | M1: COM, ET (3/4%) | N1: TC | O1: TM | P1: FS | Q1: LIEU ACHAT | R1: NUMERO DU BILLET | S1: NBRE SGTS | T1: AVANCE | U1: AVANCE 02 | V1: AVANCE 03 | W1: RGLT | X1: SOLDE | Y1: DATE RGLT | Z1: MODE RGLT | AA1: OBSERVATION | AB1: TM | AC1: APPRO | AD1: 17905765 | AF1: 17905765 | AI1: 2522688 | AM1: 4143919
A2: 45778 | B2: KP | C2: 29MAY-09JUN | D2: DLA-ABJ-DLA | E2: 00392/05/2025 | F2: MRS MANEKEUNG | G2: MANEKEUNG EPSE YOUMBI CHARLOTTE | H2: MRS HEUNA | I2: 32000 | N2: 426800 | O2: 394420 | P2: =N2-O2 | Q2: GOLITE | R2: ETKT 0329588273785 | S2: 4 | W2: 426800 | X2: =N2-T2-W2 | Y2: 45778 | Z2: OM | AB2: =O2 | AD2: 18725205 | AE2: 1213860 | AF2: =AF1-AB2+AE2+AC2 | AI2: =AI1-AG2+AH2 | AM2: 4143919
A3: 45778 | B3: EK | C3: 02MAY-21JUN | D3: DXB-CDG-DXB | E3: 00393/05/2025 | F3: MR NGATCHOU | G3: FOKOM FOTSO/JULES BORIS | H3: DG | N3: 2870920 | O3: 2570120 | P3: =N3-O3 | Q3: BLUEBERRY | R3: ETKT 1763556329916 | S3: BB | T3: 2500000 | W3: 370000 | X3: =N3-T3-W3 | Y3: 05/05/2025 09/05/2025 | Z3: CAISSE | AA3: 09MAY. | AB3: 0 | AF3: =AF2-AB3+AE3+AC3 | AI3: =AI2-AG3+AH3 | AM3: 4143919
A4: 45779 | B4: HF | C4: 02MAY-03MAY | D4: ABJ-DLA-ABJ | E4: 00387/05/2025 | F4: MR ONANA | G4: NNOMO MEZUI/CHERILLE OLIVIA MRS | H4: DG | I4: 705900 | N4: 1295920 | O4: 1135420 | P4: =N4-O4 | Q4: GOLITE | R4: ETKT 4839588273786 | S4: 2 | W4: 1295920 | X4: =N4-T4-W4 | Y4: 45800 | Z4: CAISSE | AB4: =O4 | AD4: 17589785 | AF4: =AF3-AB4+AE4+AC4 | AI4: =AI3-AG4+AH4 | AM4: 4143919
A5: 02/05/22025 | B5: AF | C5: 02MAY-16MAY | D5: YUL-DLA-YU | E5: 00394/05/2025 | F5: MRS FRANCA | G5: FOTSO THERESE ODILE | H5: DG | I5: 605900 | N5: 1423700 | O5: 1160120 | P5: =N5-O5 | Q5: GOLITE | R5: ETKT 0579588273787 | S5: 4 | W5: 1423700 | X5: =N5-T5-W5 | Y5: 45778 | Z5: CAISSE | AB5: =O5 | AF5: =AF4-AB5+AE5+AC5 | AI5: =AI4-AG5+AH5 | AM5: 4143919
A6: 45779 | B6: QC | C6: 08MAY-11MAY | D6: NSI-DLA-NSI | E6: 00396/05/2025 | F6: MRS ESSO | G6: MARIAME RAISSA, MFOUTE PEPOUORE | H6: DG | N6: 104700 | O6: 89340 | P6: =N6-O6 | Q6: KIU | R6: ETKT 0400300037076 | W6: 104500 | X6: =N6-T6-W6 | Y6: 45817 | Z6: CAISSE | AA6: 45785 | AB6: 0 | AF6: =AF5-AB6+AE6+AC6 | AG6: 89340 | AI6: =AI5-AG6+AH6 | AM6: 4143919
A7: 45779 | B7: AF | C7: 04MAY-07MAY | D7: CDG-NKC-CDG | E7: 00395/05/2025 | F7: PIVOTAL | G7: LEAUTIER/ANN FRANCES MRS | H7: DG | N7: 5346800 | O7: 5248600 | P7: =N7-O7 | Q7: AMADEUS | R7: ETKT 057 6376931402 | X7: =N7-T7-W7 | AB7: =O7 | AF7: =AF6-AB7+AE7+AC7 | AI7: =AI6-AG7+AH7 | AM7: 4143919
A8: 45780 | B8: J7 | C8: 04MAY-09MAY | D8: DLA-LBV-DLA | E8: 00397/05/2025 | F8: HORUS | G8: NGANI MEIGNIDON DIFFO MIRELLE NICAISE ELISE | H8: DG | J8: 98700 | K8: 35000 | L8: 63700 | M8: J7 | N8: 98700 | O8: 35000 | P8: =N8-O8 | Q8: J7 | R8: ETKT 2770047170619 | S8: EXCHANGE | W8: 98700 | X8: =N8-T8-W8 | Y8: 45842 | Z8: V/R | AB8: 0 | AF8: =AF7-AB8+AE8+AC8 | AI8: =AI7-AG8+AH8 | AM8: 4143919
A9: 45751 | B9: KP | C9: 04MAY-05AUG | D9: DLA-BGF-DLA | E9: 00398/05/2025 | F9: CANAL+ | G9: BOUJEKE TCHEKOULONG/WILLIAM MR | H9: DG | I9: 32100 | N9: 498920 | O9: 343655 | P9: =N9-O9 | Q9: GOLITE | R9: ETKT 0329588273788 | S9: 2 | W9: 498920 | X9: =N9-T9-W9 | Y9: 45799 | Z9: V/R | AB9: =O9 | AD9: 10986710 | AE9: 149300 | AF9: =AF8-AB9+AE9+AC9 | AI9: =AI8-AG9+AH9 | AM9: 4143919
A10: 45782 | B10: AF | C10: 25MAY-28MAY | D10: CDG-DXB-CDG | E10: 00401/02/2025 | F10: HARVEST | G10: DIVOUX/JEAN MARC | H10: DG | I10: 983300 | N10: 1258900 | O10: 1223800 | P10: =N10-O10 | Q10: GOLITE | R10: ETKT 0579588273789 | S10: 2 | W10: 1258900 | X10: =N10-T10-W10 | Y10: 45779 | Z10: V/R | AB10: =O10 | AF10: =AF9-AB10+AE10+AC10 | AI10: =AI9-AG10+AH10 | AM10: 4143919
A11: 45782 | B11: AF | C11: 24MAY-28MAY | D11: JFK-DXB-JFK | E11: 00400/05/2025 | F11: HARVEST | G11: TENGA/FABRICE | H11: DG | I11: 1639000 | N11: 2389900 | O11: 2326200 | P11: =N11-O11 | Q11: GOLITE | R11: ETKT 0579588273791 | S11: 4 | W11: 2389900 | X11: =N11-T11-W11 | Y11: 45779 | Z11: V/R | AB11: =O11 | AF11: =AF10-AB11+AE11+AC11 | AI11: =AI10-AG11+AH11 | AM11: 4143919
A12: 45782 | B12: HF | C12: 13MAY-17MAY | D12: DLA-ABJ-DLA | E12: 00399/05/2025 | F12: CANAL+ | G12: TAMBA ZAPO/PAUL ZEPHYRIN | H12: DG | I12: 140600 | N12: 590800 | O12: 490120 | P12: =N12-O12 | Q12: GOLITE | R12: ETKT 4839588273790 | S12: 2 | X12: =N12-T12-W12 | AB12: =O12 | AD12: 6946590 | AF12: =AF11-AB12+AE12+AC12 | AI12: =AI11-AG12+AH12 | AM12: 4143919
A13: 45782 | E13: 00390/05/2025 | F13: SAFARI LOGISTICS | G13: TCHATCHOUA SUZANNE LINDA | N13: 20000 | O13: 0 | P13: =N13-O13 | R13: RESERVATION HOTEL | W13: 20000 | X13: =N13-T13-W13 | Y13: 45849 | Z13: BANQUE | AA13: CHQ 1399555 | AB13: =O13
A14: 45783 | B14: AF | C14: 10JUN-14JUN-19JUN-22JUN | D14: DLA-CDG-MRS-CDG-DLA | E14: 00404/05/2025 | F14: CANAL+ | G14: MBIATCHOU/LIONEL | H14: DG | I14: 594900 | N14: 1227980 | O14: 949620 | P14: =N14-O14 | Q14: GOLITE | R14: ETKT 0579588273792 | S14: 4 | W14: 1227980 | X14: =N14-T14-W14 | Y14: 45813 | Z14: V/R | AB14: =O14 | AF14: =AF12-AB14+AE14+AC14 | AI14: =AI12-AG14+AH14 | AM14: 4143919
A15: 45783 | B15: AF | C15: 17MAY-05JUN | D15: DLA-YUL-DLA | E15: 00403/05/2025 | F15: MR NGUETSE | G15: NGUETSE YMELE/MATHIAS | H15: DG | I15: 466800 | N15: 997520 | O15: 941620 | P15: =N15-O15 | Q15: GOLITE | R15: ETKT 0579588273793 | S15: 4 | W15: 997520 | X15: =N15-T15-W15 | Y15: 45783 | Z15: CAISSE | AB15: =O15 | AD15: 5055350 | AF15: =AF14-AB15+AE15+AC15 | AI15: =AI14-AG15+AH15 | AM15: 4143919
A16: 45783 | B16: J7 | C16: 07MAY. | D16: DLA-SSG | E16: 00402/05/2025 | F16: BANGE BANK | G16: OBIANG AYANG JOSE MANUEL BILE | H16: DG | N16: 230000 | O16: 170000 | P16: =N16-O16 | Q16: J7 | R16: ETKT 27723938326 | X16: =N16-T16-W16 | AB16: 0 | AF16: =AF15-AB16+AE16+AC16 | AI16: =AI15-AG16+AH16 | AM16: 4143919
A17: 45784 | B17: KP | C17: 23MAY-31MAY | D17: NSI-NDJ-NSI | E17: 00411/05/2025 | F17: CANAL+ | G17: MFOULA/JULIENNE | H17: DG | I17: 96300 | N17: 443920 | O17: 348005 | P17: =N17-O17 | Q17: GOLITE | R17: ETKT 0329588273794 | S17: 2 | W17: 443920 | X17: =N17-T17-W17 | Y17: 45821 | Z17: V/R | AB17: =O17 | AF17: =AF16-AB17+AE17+AC17 | AI17: =AI16-AG17+AH17 | AM17: 4143919
A18: 45784 | B18: KP | C18: 23MAY-06JUN | D18: NSI-NDJ-DLA | E18: 00410/05/2025 | F18: CANAL+ | G18: TCHAMKO EPSE MBU | H18: DG | I18: 88300 | N18: 449920 | O18: 341305 | P18: =N18-O18 | Q18: GOLITE | R18: ETKT 0329588273795 | S18: 2 | W18: 449920 | X18: =N18-T18-W18 | Y18: 45821 | Z18: V/R | AB18: =O18 | AF18: =AF17-AB18+AE18+AC18 | AI18: =AI17-AG18+AH18 | AM18: 4143919
A19: 45784 | B19: KP | C19: 10MAY-18MAY | D19: DLA-NDJ-DLA | E19: 00409/05/2025 | F19: CANAL+ | G19: MBALLA NKOA/STEV | H19: DG | I19: 159200 | N19: 529700 | O19: 428805 | P19: =N19-O19 | Q19: GOLITE | R19: ETKT 0329588273796 | S19: 2 | W19: 529700 | X19: =N19-T19-W19 | Y19: 45821 | Z19: V/R | AB19: =O19 | AF19: =AF18-AB19+AE19+AC19 | AI19: =AI18-AG19+AH19 | AM19: 4143919
A20: 45784 | B20: AF | C20: 04JUN-11JUN | D20: DLA-CDG-DLA | E20: 00408/05/2025 | F20: CANAL+ | G20: NTUMBA NDAYA EPS | H20: DG | I20: 387200 | J20: 387200 | K20: 387200 | L20: 387200 | M20: 387200 | N20: 940850 | O20: 702420 | P20: =N20-O20 | Q20: GOLITE | R20: ETKT 0579588273797 | S20: 2 | X20: =N20-T20-W20 | AB20: =O20 | AF20: =AF19-AB20+AE20+AC20 | AI20: =AI19-AG20+AH20 | AM20: 4143919
A21: 45784 | B21: AF | C21: 11MAY-18MAY | D21: ABJ-CDG-ABJ | E21: 00407/05/2025 | F21: MR ONANA | G21: .LOHOUES/YEDMELY EMMANUELLA JESUS MRS | H21: DG | N21: 8796800 | O21: 8566200 | P21: =N21-O21 | Q21: AMADEUS | R21: ETKT 0576376934867 | T21: 1146525 | W21: 7650275 | X21: =N21-T21-W21 | Y21: 23/05/2025 13/06/2025 | Z21: CAISSE | AB21: =O21 | AC21: 15000000 | AF21: =AF20-AB21+AE21+AC21 | AI21: =AI20-AG21+AH21 | AM21: 4143919
A22: 45784 | B22: QC | C22: 11MAY. | D22: DLA-NGE | E22: 00406/05/2025 | F22: MRS TSOPFACK | G22: MARIE MARTINE/TSOPFACK ZEFACK | H22: MR LUCIEN | N22: 66970 | O22: 64470 | P22: =N22-O22 | Q22: KIU | R22: ETKT 0400300037077 | W22: 66970 | X22: =N22-T22-W22 | Y22: 45785 | Z22: CAISSE | AB22: 0 | AF22: =AF21-AB22+AE22+AC22 | AG22: 64470 | AI22: =AI21-AG22+AH22 | AM22: 4143919
A23: 45784 | B23: QC | C23: 08MAY-08MAY | D23: DLA-NSI-DLA | E23: 00405/05/2025 | F23: MR KEMGAM | G23: LEONARD/KEMGAN NGUETCHOM | H23: MR LUCIEN | N23: 84000 | O23: 81540 | P23: =N23-O23 | Q23: KIU | R23: ETKT 0400300037078 | W23: 84000 | X23: =N23-T23-W23 | Y23: 45785 | Z23: CAISSE | AB23: 0 | AF23: =AF22-AB23+AE23+AC23 | AG23: 81540 | AI23: =AI22-AG23+AH23 | AM23: 4143919
A24: 45784 | B24: AF | C24: 13JUN-20JUN | D24: DLA-CDG-DLA | E24: 00420/05/2025 | F24: CANAL+ | G24: TAMBA ZAPO/PAUL ZEPHYRIN | H24: DG | N24: 1012900 | O24: 1012900 | P24: =N24-O24 | Q24: GALILEO | R24: ETKT 0579588273797 | S24: FICTIF | X24: =N24-T24-W24 | AB24: =O24 | AF24: =AF23-AB24+AE24+AC24 | AI24: =AI23-AG24+AH24 | AM24: 4143919
A25: 45785 | B25: SN | C25: 06JUN-14JUN | D25: DLA-MAD-DLA | E25: 00418/05/2025 | F25: MR DJOUAKA | G25: DJOUAKA/ALAIN ROGER MR | I25: 1129100 | N25: 1945920 | O25: 1517820 | P25: =N25-O25 | Q25: NDC | R25: ETKT 0829049042874 | T25: 1000000 | W25: 945920 | X25: =N25-T25-W25 | Y25: 07/05/2025 27/05/2025 | Z25: V/R | AB25: =O25 | AF25: =AF24-AB25+AE25+AC25 | AI25: =AI24-AG25+AH25 | AM25: 4143919
A26: 45785 | B26: SN | C26: 06JUN-14JUN | D26: DLA-MAD-DLA | E26: 00419/05/2025 | F26: MR DJOUAKA | G26: KIFACK BOUKENG EP DJOUAKA/FLORENCE | I26: 1129100 | N26: 1945920 | O26: 1517820 | P26: =N26-O26 | Q26: NDC | R26: ETKT 0829049042875 | T26: 1000000 | W26: 945920 | X26: =N26-T26-W26 | Y26: 07/05/2025 27/05/2025 | Z26: V/R | AB26: =O26 | AF26: =AF25-AB26+AE26+AC26 | AI26: =AI25-AG26+AH26 | AM26: 4143919
A27: 45785 | B27: SN | C27: 13MAY. | D27: ABJ-LHR | E27: 00415/05/2025 | F27: PIVOTAL | G27: APHING KOUASSI/LYNDA MRS | H27: DG | I27: 1281100 | N27: 1579800 | O27: 1449600 | P27: =N27-O27 | Q27: NDC | R27: ETKT 0829049042876 | X27: =N27-T27-W27 | AB27: =O27 | AF27: =AF26-AB27+AE27+AC27 | AI27: =AI26-AG27+AH27 | AM27: 4143919
A28: 45785 | B28: SN08MAY-12MAY | C28: 08MAY-12MAY | D28: FIH-BRU-FIH | E28: 00417/05/2025 | F28: MRS ELANGA | G28: NJONGUO TIALEFACK/JULIUS | H28: DG | I28: 2659300 | N28: 3040300 | O28: 2940300 | P28: =N28-O28 | Q28: NDC | R28: ETKT 0829049042877 | W28: 3040300 | X28: =N28-T28-W28 | Y28: 45800 | Z28: CAISSE | AB28: =O28 | AF28: =AF27-AB28+AE28+AC28 | AI28: =AI27-AG28+AH28 | AM28: 4143919
A29: 45785 | B29: AF | C29: 14MAY-24MAY | D29: ABJ-LHR-ABJ | E29: 00412/05/2025 | F29: PIVOTAL | G29: HOT JUNIOR THIERRY | H29: DG | I29: 4896900 | N29: 6433100 | O29: 5641300 | P29: =N29-O29 | Q29: AMADEUS/BLEUBERRY | R29: ETKT 0576376932795 | X29: =N29-T29-W29 | AB29: 0 | AF29: =AF28-AB29+AE29+AC29 | AI29: =AI28-AG29+AH29 | AM29: 4143919
A30: 45785 | B30: AF | C30: 31MAY. | D30: ABJ-ZHR | E30: 00413/05/2025 | F30: PIVOTAL | G30: HOT JUNIOR THIERRY | H30: DG | I30: 2463700 | N30: 2895800 | O30: 2794400 | P30: =N30-O30 | Q30: AMADEUS/BLEUBERRY | R30: ETKT 0576376932897 | X30: =N30-T30-W30 | AB30: 0 | AF30: =AF29-AB30+AE30+AC30 | AI30: =AI29-AG30+AH30 | AM30: 4143919
A31: 45785 | B31: AF | C31: 14MAY. | D31: ABJ-LHR | E31: 00414/05/2025 | F31: PIVOTAL | G31: TAH/SIDI | H31: DG | N31: 3246300 | O31: 3166300 | P31: =N31-O31 | Q31: AMADEUS/BLEUBERRY | R31: ETKT 0576376932886 | X31: =N31-T31-W31 | AB31: 0 | AF31: =AF30-AB31+AE31+AC31 | AI31: =AI30-AG31+AH31 | AM31: 4143919
A32: 45785 | B32: HF | C32: 27MAY-31MAY | D32: DLA-ABJ-DLA | E32: 00416/05/2025 | F32: PIVOTAL | G32: EKOUTI BENOIT THIERRY | H32: DG | N32: 564800 | O32: 504800 | P32: =N32-O32 | Q32: AMADEUS | R32: ETKT 4836376935105 | X32: =N32-T32-W32 | AB32: =O32 | AD32: 1738255 | AF32: =AF31-AB32+AE32+AC32 | AI32: =AI31-AG32+AH32 | AM32: 4143919
A33: 45786 | B33: AF | C33: 10MAY-14MAY | D33: CDG-ABJ-CDG | E33: 00421/05/2025 | F33: PIVOTAL | G33: LEAUTIER/ANN FRANCES MRS | H33: DG | N33: 22000 | O33: 0 | P33: =N33-O33 | Q33: AMADEUS | R33: ETKT 0576376935746 | S33: EXCHANGE | X33: =N33-T33-W33 | AB33: =O33 | AF33: =AF32-AB33+AE33+AC33 | AI33: =AI32-AG33+AH33 | AM33: 4143919
A34: 45786 | B34: MS | C34: 20MAY. | D34: DLA-CMN | E34: 00422/05/2025 | F34: MR TAPA | G34: TAPA GAEL SYLVESTRE | H34: MME HEUNA | N34: 359700 | O34: 350420 | P34: =N34-O34 | Q34: AMADEUS | R34: ETKT 0776376935741 | T34: 300000 | W34: 59700 | X34: =N34-T34-W34 | Y34: 09/05/2025 12/05/2025 | Z34: CAISSE | AB34: =O34 | AF34: =AF33-AB34+AE34+AC34 | AI34: =AI33-AG34+AH34 | AM34: 4143919
